Workbook

Sheet 2012 Team Player Stats
A1: Rk | B1: Pos | C1: Name | D1: Type | E1: Age | F1: G | G1: PA | H1: AB | I1: R | J1: H | K1: 2B | L1: 3B | M1: HR | N1: RBI | O1: SB | P1: CS | Q1: BB | R1: SO | S1: BA | T1: OBP | U1: SLG | V1: OPS | W1: OPS+ | X1: TB | Y1: GDP | Z1: HBP | AA1: SH | AB1: SF | AC1: IBB
A2: 45 | B2: P | C2: Adam Warren | D2: =VLOOKUP(C2,Players!B:H,7,FALSE) -> Pitcher | E2: 24 | F2: 1 | G2: 0 | H2: 0 | I2: 0 | J2: 0 | K2: 0 | L2: 0 | M2: 0 | N2: 0 | O2: 0 | P2: 0 | Q2: 0 | R2: 0 | X2: 0 | Y2: 0 | Z2: 0 | AA2: 0 | AB2: 0 | AC2: 0
A3: 5 | B3: 3B | C3: Alex Rodriguez | D3: =VLOOKUP(C3,Players!B:H,7,FALSE) -> Infielder | E3: 36 | F3: 122 | G3: 529 | H3: 463 | I3: 74 | J3: 126 | K3: 17 | L3: 1 | M3: 18 | N3: 57 | O3: 13 | P3: 1 | Q3: 51 | R3: 116 | S3: 0.272 | T3: 0.353 | U3: 0.43 | V3: 0.783 | W3: 113 | X3: 199 | Y3: 13 | Z3: 10 | AA3: 0 | AB3: 5 | AC3: 3
A4: 10 | B4: UT | C4: Andruw Jones | D4: =VLOOKUP(C4,Players!B:H,7,FALSE) -> Outfielder | E4: 35 | F4: 94 | G4: 269 | H4: 233 | I4: 27 | J4: 46 | K4: 7 | L4: 0 | M4: 14 | N4: 34 | O4: 0 | P4: 0 | Q4: 28 | R4: 71 | S4: 0.197 | T4: 0.294 | U4: 0.408 | V4: 0.701 | W4: 89 | X4: 95 | Y4: 2 | Z4: 5 | AA4: 0 | AB4: 3 | AC4: 1
A5: 25 | B5: P | C5: Andy Pettitte | D5: =VLOOKUP(C5,Players!B:H,7,FALSE) -> Pitcher | E5: 40 | F5: 12 | G5: 5 | H5: 4 | I5: 0 | J5: 1 | K5: 0 | L5: 0 | M5: 0 | N5: 0 | O5: 0 | P5: 0 | Q5: 0 | R5: 2 | S5: 0.25 | T5: 0.25 | U5: 0.25 | V5: 0.5 | W5: 38 | X5: 1 | Y5: 0 | Z5: 0 | AA5: 1 | AB5: 0 | AC5: 0
A6: 33 | B6: P | C6: Boone Logan | D6: =VLOOKUP(C6,Players!B:H,7,FALSE) -> Pitcher | E6: 27 | F6: 80 | G6: 0 | H6: 0 | I6: 0 | J6: 0 | K6: 0 | L6: 0 | M6: 0 | N6: 0 | O6: 0 | P6: 0 | Q6: 0 | R6: 0 | X6: 0 | Y6: 0 | Z6: 0 | AA6: 0 | AB6: 0 | AC6: 0
A7: 17 | B7: LF | C7: Brett Gardner | D7: =VLOOKUP(C7,Players!B:H,7,FALSE) -> Outfielder | E7: 28 | F7: 16 | G7: 37 | H7: 31 | I7: 7 | J7: 10 | K7: 2 | L7: 0 | M7: 0 | N7: 3 | O7: 2 | P7: 2 | Q7: 5 | R7: 7 | S7: 0.323 | T7: 0.417 | U7: 0.387 | V7: 0.804 | W7: 122 | X7: 12 | Y7: 0 | Z7: 0 | AA7: 1 | AB7: 0 | AC7: 0
A8: 16 | B8: UT | C8: Casey McGehee | D8: =VLOOKUP(C8,Players!B:H,7,FALSE) -> Infielder | E8: 29 | F8: 22 | G8: 59 | H8: 53 | I8: 9 | J8: 8 | K8: 3 | L8: 0 | M8: 1 | N8: 6 | O8: 0 | P8: 0 | Q8: 5 | R8: 10 | S8: 0.151 | T8: 0.22 | U8: 0.264 | V8: 0.484 | W8: 32 | X8: 14 | Y8: 3 | Z8: 0 | AA8: 0 | AB8: 1 | AC8: 0
A9: 26 | B9: P | C9: CC Sabathia | D9: =VLOOKUP(C9,Players!B:H,7,FALSE) -> Pitcher | E9: 31 | F9: 28 | G9: 5 | H9: 5 | I9: 0 | J9: 0 | K9: 0 | L9: 0 | M9: 0 | N9: 0 | O9: 0 | P9: 0 | Q9: 0 | R9: 1 | S9: 0 | T9: 0 | U9: 0 | V9: 0 | W9: -100 | X9: 0 | Y9: 0 | Z9: 0 | AA9: 0 | AB9: 0 | AC9: 0
A10: 35 | B10: P | C10: Chad Qualls | D10: =VLOOKUP(C10,Players!B:H,7,FALSE) -> Pitcher | E10: 33 | F10: 8 | G10: 0 | H10: 0 | I10: 0 | J10: 0 | K10: 0 | L10: 0 | M10: 0 | N10: 0 | O10: 0 | P10: 0 | Q10: 0 | R10: 0 | X10: 0 | Y10: 0 | Z10: 0 | AA10: 0 | AB10: 0 | AC10: 0
A11: 19 | B11: OF | C11: Chris Dickerson | D11: =VLOOKUP(C11,Players!B:H,7,FALSE) -> Outfielder | E11: 30 | F11: 25 | G11: 17 | H11: 14 | I11: 5 | J11: 4 | K11: 0 | L11: 0 | M11: 2 | N11: 5 | O11: 3 | P11: 0 | Q11: 3 | R11: 5 | S11: 0.286 | T11: 0.412 | U11: 0.714 | V11: 1.126 | W11: 199 | X11: 10 | Y11: 1 | Z11: 0 | AA11: 0 | AB11: 0 | AC11: 0
A12: 13 | B12: C | C12: Chris Stewart | D12: =VLOOKUP(C12,Players!B:H,7,FALSE) -> Catcher | E12: 30 | F12: 55 | G12: 157 | H12: 141 | I12: 15 | J12: 34 | K12: 8 | L12: 0 | M12: 1 | N12: 13 | O12: 2 | P12: 0 | Q12: 10 | R12: 21 | S12: 0.241 | T12: 0.292 | U12: 0.319 | V12: 0.611 | W12: 67 | X12: 45 | Y12: 1 | Z12: 1 | AA12: 3 | AB12: 2 | AC12: 0
A13: 31 | B13: P | C13: Clay Rapada | D13: =VLOOKUP(C13,Players!B:H,7,FALSE) -> Pitcher | E13: 31 | F13: 70 | G13: 0 | H13: 0 | I13: 0 | J13: 0 | K13: 0 | L13: 0 | M13: 0 | N13: 0 | O13: 0 | P13: 0 | Q13: 0 | R13: 0 | X13: 0 | Y13: 0 | Z13: 0 | AA13: 0 | AB13: 0 | AC13: 0
A14: 41 | B14: P | C14: Cody Eppley | D14: =VLOOKUP(C14,Players!B:H,7,FALSE) -> Pitcher | E14: 26 | F14: 59 | G14: 0 | H14: 0 | I14: 0 | J14: 0 | K14: 0 | L14: 0 | M14: 0 | N14: 0 | O14: 0 | P14: 0 | Q14: 0 | R14: 0 | X14: 0 | Y14: 0 | Z14: 0 | AA14: 0 | AB14: 0 | AC14: 0
A15: 42 | B15: P | C15: Cory Wade | D15: =VLOOKUP(C15,Players!B:H,7,FALSE) -> Pitcher | E15: 29 | F15: 39 | G15: 0 | H15: 0 | I15: 0 | J15: 0 | K15: 0 | L15: 0 | M15: 0 | N15: 0 | O15: 0 | P15: 0 | Q15: 0 | R15: 0 | X15: 0 | Y15: 0 | Z15: 0 | AA15: 0 | AB15: 0 | AC15: 0
A16: 7 | B16: CF | C16: Curtis Granderson | D16: =VLOOKUP(C16,Players!B:H,7,FALSE) -> Outfielder | E16: 31 | F16: 160 | G16: 684 | H16: 596 | I16: 102 | J16: 138 | K16: 18 | L16: 4 | M16: 43 | N16: 106 | O16: 10 | P16: 3 | Q16: 75 | R16: 195 | S16: 0.232 | T16: 0.319 | U16: 0.492 | V16: 0.811 | W16: 117 | X16: 293 | Y16: 5 | Z16: 5 | AA16: 1 | AB16: 7 | AC16: 4
A17: 34 | B17: P | C17: D.J. Mitchell | D17: =VLOOKUP(C17,Players!B:H,7,FALSE) -> Pitcher | E17: 25 | F17: 4 | G17: 0 | H17: 0 | I17: 0 | J17: 0 | K17: 0 | L17: 0 | M17: 0 | N17: 0 | O17: 0 | P17: 0 | Q17: 0 | R17: 0 | X17: 0 | Y17: 0 | Z17: 0 | AA17: 0 | AB17: 0 | AC17: 0
A18: 21 | B18: OF | C18: Darnell McDonald | D18: =VLOOKUP(C18,Players!B:H,7,FALSE) -> Outfielder | E18: 33 | F18: 4 | G18: 4 | H18: 4 | I18: 0 | J18: 0 | K18: 0 | L18: 0 | M18: 0 | N18: 0 | O18: 0 | P18: 0 | Q18: 0 | R18: 2 | S18: 0 | T18: 0 | U18: 0 | V18: 0 | W18: -100 | X18: 0 | Y18: 0 | Z18: 0 | AA18: 0 | AB18: 0 | AC18: 0
A19: 30 | B19: P | C19: David Aardsma | D19: =VLOOKUP(C19,Players!B:H,7,FALSE) -> Pitcher | E19: 30 | F19: 1 | G19: 0 | H19: 0 | I19: 0 | J19: 0 | K19: 0 | L19: 0 | M19: 0 | N19: 0 | O19: 0 | P19: 0 | Q19: 0 | R19: 0 | X19: 0 | Y19: 0 | Z19: 0 | AA19: 0 | AB19: 0 | AC19: 0
A20: 37 | B20: P | C20: David Phelps | D20: =VLOOKUP(C20,Players!B:H,7,FALSE) -> Pitcher | E20: 25 | F20: 33 | G20: 0 | H20: 0 | I20: 0 | J20: 0 | K20: 0 | L20: 0 | M20: 0 | N20: 0 | O20: 0 | P20: 0 | Q20: 0 | R20: 0 | X20: 0 | Y20: 0 | Z20: 0 | AA20: 0 | AB20: 0 | AC20: 0
A21: 44 | B21: P | C21: David Robertson | D21: =VLOOKUP(C21,Players!B:H,7,FALSE) -> Pitcher | E21: 27 | F21: 65 | G21: 0 | H21: 0 | I21: 0 | J21: 0 | K21: 0 | L21: 0 | M21: 0 | N21: 0 | O21: 0 | P21: 0 | Q21: 0 | R21: 0 | X21: 0 | Y21: 0 | Z21: 0 | AA21: 0 | AB21: 0 | AC21: 0
A22: 4 | B22: SS | C22: Derek Jeter | D22: =VLOOKUP(C22,Players!B:H,7,FALSE) -> Infielder | E22: 38 | F22: 159 | G22: 740 | H22: 683 | I22: 99 | J22: 216 | K22: 32 | L22: 0 | M22: 15 | N22: 58 | O22: 9 | P22: 4 | Q22: 45 | R22: 90 | S22: 0.316 | T22: 0.362 | U22: 0.429 | V22: 0.791 | W22: 115 | X22: 293 | Y22: 24 | Z22: 5 | AA22: 6 | AB22: 1 | AC22: 1
A23: 36 | B23: P | C23: Derek Lowe | D23: =VLOOKUP(C23,Players!B:H,7,FALSE) -> Pitcher | E23: 39 | F23: 17 | G23: 0 | H23: 0 | I23: 0 | J23: 0 | K23: 0 | L23: 0 | M23: 0 | N23: 0 | O23: 0 | P23: 0 | Q23: 0 | R23: 0 | X23: 0 | Y23: 0 | Z23: 0 | AA23: 0 | AB23: 0 | AC23: 0
A24: 15 | B24: OF | C24: Dewayne Wise | D24: =VLOOKUP(C24,Players!B:H,7,FALSE) -> Outfielder | E24: 34 | F24: 56 | G24: 63 | H24: 61 | I24: 11 | J24: 16 | K24: 3 | L24: 1 | M24: 3 | N24: 8 | O24: 7 | P24: 0 | Q24: 2 | R24: 12 | S24: 0.262 | T24: 0.286 | U24: 0.492 | V24: 0.778 | W24: 107 | X24: 30 | Y24: 1 | Z24: 0 | AA24: 0 | AB24: 0 | AC24: 0
A25: 14 | B25: UT | C25: Eduardo Nunez | D25: =VLOOKUP(C25,Players!B:H,7,FALSE) -> Infielder | E25: 25 | F25: 38 | G25: 100 | H25: 89 | I25: 14 | J25: 26 | K25: 4 | L25: 1 | M25: 1 | N25: 11 | O25: 11 | P25: 2 | Q25: 6 | R25: 12 | S25: 0.292 | T25: 0.33 | U25: 0.393 | V25: 0.723 | W25: 97 | X25: 35 | Y25: 1 | Z25: 1 | AA25: 0 | AB25: 4 | AC25: 0
A26: 9 | B26: DH | C26: Eric Chavez | D26: =VLOOKUP(C26,Players!B:H,7,FALSE) -> Infielder | E26: 34 | F26: 113 | G26: 313 | H26: 278 | I26: 36 | J26: 78 | K26: 12 | L26: 0 | M26: 16 | N26: 37 | O26: 0 | P26: 0 | Q26: 30 | R26: 59 | S26: 0.281 | T26: 0.348 | U26: 0.496 | V26: 0.845 | W26: 127 | X26: 138 | Y26: 10 | Z26: 1 | AA26: 0 | AB26: 4 | AC26: 3
A27: 23 | B27: C | C27: Francisco Cervelli | D27: =VLOOKUP(C27,Players!B:H,7,FALSE) -> Catcher | E27: 26 | F27: 3 | G27: 2 | H27: 1 | I27: 1 | J27: 0 | K27: 0 | L27: 0 | M27: 0 | N27: 0 | O27: 0 | P27: 0 | Q27: 1 | R27: 0 | S27: 0 | T27: 0.5 | U27: 0 | V27: 0.5 | W27: 55 | X27: 0 | Y27: 0 | Z27: 0 | AA27: 0 | AB27: 0 | AC27: 0
A28: 29 | B28: P | C28: Freddy Garcia | D28: =VLOOKUP(C28,Players!B:H,7,FALSE) -> Pitcher | E28: 35 | F28: 30 | G28: 1 | H28: 1 | I28: 0 | J28: 0 | K28: 0 | L28: 0 | M28: 0 | N28: 0 | O28: 0 | P28: 0 | Q28: 0 | R28: 1 | S28: 0 | T28: 0 | U28: 0 | V28: 0 | W28: -100 | X28: 0 | Y28: 0 | Z28: 0 | AA28: 0 | AB28: 0 | AC28: 0
A29: 28 | B29: P | C29: Hiroki Kuroda | D29: =VLOOKUP(C29,Players!B:H,7,FALSE) -> Pitcher | E29: 37 | F29: 33 | G29: 2 | H29: 2 | I29: 0 | J29: 0 | K29: 0 | L29: 0 | M29: 0 | N29: 0 | O29: 0 | P29: 0 | Q29: 0 | R29: 1 | S29: 0 | T29: 0 | U29: 0 | V29: 0 | W29: -100 | X29: 0 | Y29: 0 | Z29: 0 | AA29: 0 | AB29: 0 | AC29: 0
A30: 11 | B30: OF | C30: Ichiro Suzuki | D30: =VLOOKUP(C30,Players!B:H,7,FALSE) -> Outfielder | E30: 38 | F30: 67 | G30: 240 | H30: 227 | I30: 28 | J30: 73 | K30: 13 | L30: 1 | M30: 5 | N30: 27 | O30: 14 | P30: 5 | Q30: 5 | R30: 21 | S30: 0.322 | T30: 0.34 | U30: 0.454 | V30: 0.794 | W30: 115 | X30: 103 | Y30: 2 | Z30: 2 | AA30: 5 | AB30: 1 | AC30: 1
A31: 24 | B31: P | C31: Ivan Nova | D31: =VLOOKUP(C31,Players!B:H,7,FALSE) -> Pitcher | E31: 25 | F31: 28 | G31: 9 | H31: 7 | I31: 0 | J31: 1 | K31: 0 | L31: 0 | M31: 0 | N31: 0 | O31: 0 | P31: 0 | Q31: 0 | R31: 6 | S31: 0.143 | T31: 0.143 | U31: 0.143 | V31: 0.286 | W31: -21 | X31: 1 | Y31: 0 | Z31: 0 | AA31: 2 | AB31: 0 | AC31: 0
A32: 12 | B32: UT | C32: Jayson Nix | D32: =VLOOKUP(C32,Players!B:H,7,FALSE) -> Infielder | E32: 29 | F32: 74 | G32: 202 | H32: 177 | I32: 24 | J32: 43 | K32: 13 | L32: 0 | M32: 4 | N32: 18 | O32: 6 | P32: 3 | Q32: 14 | R32: 53 | S32: 0.243 | T32: 0.306 | U32: 0.384 | V32: 0.69 | W32: 87 | X32: 68 | Y32: 4 | Z32: 2 | AA32: 9 | AB32: 0 | AC32: 0
A33: 32 | B33: P | C33: Joba Chamberlain | D33: =VLOOKUP(C33,Players!B:H,7,FALSE) -> Pitcher | E33: 26 | F33: 22 | G33: 0 | H33: 0 | I33: 0 | J33: 0 | K33: 0 | L33: 0 | M33: 0 | N33: 0 | O33: 0 | P33: 0 | Q33: 0 | R33: 0 | X33: 0 | Y33: 0 | Z33: 0 | AA33: 0 | AB33: 0 | AC33: 0
A34: 38 | B34: P | C34: Justin Thomas | D34: =VLOOKUP(C34,Players!B:H,7,FALSE) -> Pitcher | E34: 28 | F34: 4 | G34: 0 | H34: 0 | I34: 0 | J34: 0 | K34: 0 | L34: 0 | M34: 0 | N34: 0 | O34: 0 | P34: 0 | Q34: 0 | R34: 0 | X34: 0 | Y34: 0 | Z34: 0 | AA34: 0 | AB34: 0 | AC34: 0
A35: 40 | B35: P | C35: Mariano Rivera | D35: =VLOOKUP(C35,Players!B:H,7,FALSE) -> Pitcher | E35: 42 | F35: 9 | G35: 0 | H35: 0 | I35: 0 | J35: 0 | K35: 0 | L35: 0 | M35: 0 | N35: 0 | O35: 0 | P35: 0 | Q35: 0 | R35: 0 | X35: 0 | Y35: 0 | Z35: 0 | AA35: 0 | AB35: 0 | AC35: 0
A36: 2 | B36: 1B | C36: Mark Teixeira | D36: =VLOOKUP(C36,Players!B:H,7,FALSE) -> Infielder | E36: 32 | F36: 123 | G36: 524 | H36: 451 | I36: 66 | J36: 113 | K36: 27 | L36: 1 | M36: 24 | N36: 84 | O36: 2 | P36: 1 | Q36: 54 | R36: 83 | S36: 0.251 | T36: 0.332 | U36: 0.475 | V36: 0.807 | W36: 117 | X36: 214 | Y36: 11 | Z36: 7 | AA36: 0 | AB36: 12 | AC36: 1
A37: 22 | B37: UT | C37: Melky Mesa | D37: =VLOOKUP(C37,Players!B:H,7,FALSE) -> Pitcher | E37: 25 | F37: 3 | G37: 2 | H37: 2 | I37: 0 | J37: 1 | K37: 0 | L37: 0 | M37: 0 | N37: 1 | O37: 0 | P37: 0 | Q37: 0 | R37: 0 | S37: 0.5 | T37: 0.5 | U37: 0.5 | V37: 1 | W37: 175 | X37: 1 | Y37: 0 | Z37: 0 | AA37: 0 | AB37: 0 | AC37: 0
A38: 8 | B38: RF | C38: Nick Swisher | D38: =VLOOKUP(C38,Players!B:H,7,FALSE) -> Outfielder | E38: 31 | F38: 148 | G38: 624 | H38: 537 | I38: 75 | J38: 146 | K38: 36 | L38: 0 | M38: 24 | N38: 93 | O38: 2 | P38: 3 | Q38: 77 | R38: 141 | S38: 0.272 | T38: 0.364 | U38: 0.473 | V38: 0.837 | W38: 127 | X38: 254 | Y38: 9 | Z38: 4 | AA38: 1 | AB38: 5 | AC38: 2
A39: 27 | B39: P | C39: Phil Hughes | D39: =VLOOKUP(C39,Players!B:H,7,FALSE) -> Pitcher | E39: 26 | F39: 32 | G39: 2 | H39: 2 | I39: 0 | J39: 0 | K39: 0 | L39: 0 | M39: 0 | N39: 0 | O39: 0 | P39: 0 | Q39: 0 | R39: 1 | S39: 0 | T39: 0 | U39: 0 | V39: 0 | W39: -100 | X39: 0 | Y39: 0 | Z39: 0 | AA39: 0 | AB39: 0 | AC39: 0
A40: 43 | B40: P | C40: Rafael Soriano | D40: =VLOOKUP(C40,Players!B:H,7,FALSE) -> Pitcher | E40: 32 | F40: 69 | G40: 0 | H40: 0 | I40: 0 | J40: 0 | K40: 0 | L40: 0 | M40: 0 | N40: 0 | O40: 0 | P40: 0 | Q40: 0 | R40: 0 | X40: 0 | Y40: 0 | Z40: 0 | AA40: 0 | AB40: 0 | AC40: 0
...

Sheet Additional Player Info
A1: Rk | B1: Pos | C1: Name | D1: Type | E1: Salary | F1: Height (in) | G1: Weight | H1: Age
A2: 45 | B2: P | C2: Adam Warren | D2: =VLOOKUP(C2,Players!B:H,7,FALSE) -> Pitcher | F2: 74 | G2: =VLOOKUP(C2,Players!B:D,3,FALSE) -> 200 | H2: 24
A3: 5 | B3: 3B | C3: Alex Rodriguez | D3: =VLOOKUP(C3,Players!B:H,7,FALSE) -> Infielder | E3: 29000000 | F3: 75 | G3: =VLOOKUP(C3,Players!B:D,3,FALSE) -> 225 | H3: 36
A4: 10 | B4: UT | C4: Andruw Jones | D4: =VLOOKUP(C4,Players!B:H,7,FALSE) -> Outfielder | E4: 2000000 | F4: 73 | G4: =VLOOKUP(C4,Players!B:D,3,FALSE) -> 225 | H4: 35
A5: 25 | B5: P | C5: Andy Pettitte | D5: =VLOOKUP(C5,Players!B:H,7,FALSE) -> Pitcher | E5: 2500000 | F5: 77 | G5: =VLOOKUP(C5,Players!B:D,3,FALSE) -> 225 | H5: 40
A6: 33 | B6: P | C6: Boone Logan | D6: =VLOOKUP(C6,Players!B:H,7,FALSE) -> Pitcher | E6: 1875000 | F6: 77 | G6: =VLOOKUP(C6,Players!B:D,3,FALSE) -> 215 | H6: 27
A7: 17 | B7: LF | C7: Brett Gardner | D7: =VLOOKUP(C7,Players!B:H,7,FALSE) -> Outfielder | E7: 2800000 | F7: 70 | G7: =VLOOKUP(C7,Players!B:D,3,FALSE) -> 185 | H7: 28
A8: 16 | B8: UT | C8: Casey McGehee | D8: =VLOOKUP(C8,Players!B:H,7,FALSE) -> Infielder | F8: 73 | G8: =VLOOKUP(C8,Players!B:D,3,FALSE) -> 220 | H8: 29
A9: 26 | B9: P | C9: CC Sabathia | D9: =VLOOKUP(C9,Players!B:H,7,FALSE) -> Pitcher | E9: 23000000 | F9: 79 | G9: =VLOOKUP(C9,Players!B:D,3,FALSE) -> 290 | H9: 31
A10: 35 | B10: P | C10: Chad Qualls | D10: =VLOOKUP(C10,Players!B:H,7,FALSE) -> Pitcher | F10: 77 | G10: =VLOOKUP(C10,Players!B:D,3,FALSE) -> 240 | H10: 33
A11: 19 | B11: OF | C11: Chris Dickerson | D11: =VLOOKUP(C11,Players!B:H,7,FALSE) -> Outfielder | F11: 75 | G11: =VLOOKUP(C11,Players!B:D,3,FALSE) -> 230 | H11: 30
A12: 13 | B12: C | C12: Chris Stewart | D12: =VLOOKUP(C12,Players!B:H,7,FALSE) -> Catcher | E12: 482500 | F12: 76 | G12: =VLOOKUP(C12,Players!B:D,3,FALSE) -> 210 | H12: 30
A13: 31 | B13: P | C13: Clay Rapada | D13: =VLOOKUP(C13,Players!B:H,7,FALSE) -> Pitcher | E13: 525000 | F13: 77 | G13: =VLOOKUP(C13,Players!B:D,3,FALSE) -> 200 | H13: 31
A14: 41 | B14: P | C14: Cody Eppley | D14: =VLOOKUP(C14,Players!B:H,7,FALSE) -> Pitcher | F14: 77 | G14: =VLOOKUP(C14,Players!B:D,3,FALSE) -> 205 | H14: 26
A15: 42 | B15: P | C15: Cory Wade | D15: =VLOOKUP(C15,Players!B:H,7,FALSE) -> Pitcher | E15: 508925 | F15: 74 | G15: =VLOOKUP(C15,Players!B:D,3,FALSE) -> 185 | H15: 29
A16: 7 | B16: CF | C16: Curtis Granderson | D16: =VLOOKUP(C16,Players!B:H,7,FALSE) -> Outfielder | E16: 10000000 | F16: 73 | G16: =VLOOKUP(C16,Players!B:D,3,FALSE) -> 195 | H16: 31
A17: 34 | B17: P | C17: D.J. Mitchell | D17: =VLOOKUP(C17,Players!B:H,7,FALSE) -> Pitcher | F17: 72 | G17: =VLOOKUP(C17,Players!B:D,3,FALSE) -> 160 | H17: 25
A18: 21 | B18: OF | C18: Darnell McDonald | D18: =VLOOKUP(C18,Players!B:H,7,FALSE) -> Outfielder | F18: 71 | G18: =VLOOKUP(C18,Players!B:D,3,FALSE) -> 205 | H18: 33
A19: 30 | B19: P | C19: David Aardsma | D19: =VLOOKUP(C19,Players!B:H,7,FALSE) -> Pitcher | E19: 500000 | F19: 77 | G19: =VLOOKUP(C19,Players!B:D,3,FALSE) -> 205 | H19: 30
A20: 37 | B20: P | C20: David Phelps | D20: =VLOOKUP(C20,Players!B:H,7,FALSE) -> Pitcher | F20: 74 | G20: =VLOOKUP(C20,Players!B:D,3,FALSE) -> 200 | H20: 25
A21: 44 | B21: P | C21: David Robertson | D21: =VLOOKUP(C21,Players!B:H,7,FALSE) -> Pitcher | E21: 1600000 | F21: 71 | G21: =VLOOKUP(C21,Players!B:D,3,FALSE) -> 195 | H21: 27
A22: 4 | B22: SS | C22: Derek Jeter | D22: =VLOOKUP(C22,Players!B:H,7,FALSE) -> Infielder | E22: 16000000 | F22: 75 | G22: =VLOOKUP(C22,Players!B:D,3,FALSE) -> 195 | H22: 38
A23: 36 | B23: P | C23: Derek Lowe | D23: =VLOOKUP(C23,Players!B:H,7,FALSE) -> Pitcher | F23: 78 | G23: =VLOOKUP(C23,Players!B:D,3,FALSE) -> 230 | H23: 39
A24: 15 | B24: OF | C24: Dewayne Wise | D24: =VLOOKUP(C24,Players!B:H,7,FALSE) -> Outfielder | F24: 72 | G24: =VLOOKUP(C24,Players!B:D,3,FALSE) -> 200 | H24: 34
A25: 14 | B25: UT | C25: Eduardo Nunez | D25: =VLOOKUP(C25,Players!B:H,7,FALSE) -> Infielder | E25: 523800 | F25: 72 | G25: =VLOOKUP(C25,Players!B:D,3,FALSE) -> 185 | H25: 25
A26: 9 | B26: DH | C26: Eric Chavez | D26: =VLOOKUP(C26,Players!B:H,7,FALSE) -> Infielder | E26: 900000 | F26: 73 | G26: =VLOOKUP(C26,Players!B:D,3,FALSE) -> 215 | H26: 34
A27: 23 | B27: C | C27: Francisco Cervelli | D27: =VLOOKUP(C27,Players!B:H,7,FALSE) -> Catcher | F27: 73 | G27: =VLOOKUP(C27,Players!B:D,3,FALSE) -> 205 | H27: 26
A28: 29 | B28: P | C28: Freddy Garcia | D28: =VLOOKUP(C28,Players!B:H,7,FALSE) -> Pitcher | E28: 4000000 | F28: 76 | G28: =VLOOKUP(C28,Players!B:D,3,FALSE) -> 255 | H28: 35
A29: 28 | B29: P | C29: Hiroki Kuroda | D29: =VLOOKUP(C29,Players!B:H,7,FALSE) -> Pitcher | E29: 10000000 | F29: 73 | G29: =VLOOKUP(C29,Players!B:D,3,FALSE) -> 205 | H29: 37
A30: 11 | B30: OF | C30: Ichiro Suzuki | D30: =VLOOKUP(C30,Players!B:H,7,FALSE) -> Outfielder | F30: 71 | G30: =VLOOKUP(C30,Players!B:D,3,FALSE) -> 170 | H30: 38
A31: 24 | B31: P | C31: Ivan Nova | D31: =VLOOKUP(C31,Players!B:H,7,FALSE) -> Pitcher | E31: 527200 | F31: 76 | G31: =VLOOKUP(C31,Players!B:D,3,FALSE) -> 225 | H31: 25
A32: 12 | B32: UT | C32: Jayson Nix | D32: =VLOOKUP(C32,Players!B:H,7,FALSE) -> Infielder | F32: 71 | G32: =VLOOKUP(C32,Players!B:D,3,FALSE) -> 195 | H32: 29
A33: 32 | B33: P | C33: Joba Chamberlain | D33: =VLOOKUP(C33,Players!B:H,7,FALSE) -> Pitcher | E33: 1675000 | F33: 74 | G33: =VLOOKUP(C33,Players!B:D,3,FALSE) -> 250 | H33: 26
A34: 38 | B34: P | C34: Justin Thomas | D34: =VLOOKUP(C34,Players!B:H,7,FALSE) -> Pitcher | F34: 75 | G34: =VLOOKUP(C34,Players!B:D,3,FALSE) -> 220 | H34: 28
A35: 40 | B35: P | C35: Mariano Rivera | D35: =VLOOKUP(C35,Players!B:H,7,FALSE) -> Pitcher | E35: 15000000 | F35: 74 | G35: =VLOOKUP(C35,Players!B:D,3,FALSE) -> 195 | H35: 42
A36: 2 | B36: 1B | C36: Mark Teixeira | D36: =VLOOKUP(C36,Players!B:H,7,FALSE) -> Infielder | E36: 22500000 | F36: 75 | G36: =VLOOKUP(C36,Players!B:D,3,FALSE) -> 215 | H36: 32
A37: 22 | B37: UT | C37: Melky Mesa | D37: =VLOOKUP(C37,Players!B:H,7,FALSE) -> Pitcher | F37: 73 | G37: =VLOOKUP(C37,Players!B:D,3,FALSE) -> 190 | H37: 25
A38: 8 | B38: RF | C38: Nick Swisher | D38: =VLOOKUP(C38,Players!B:H,7,FALSE) -> Outfielder | E38: 10250000 | F38: 71 | G38: =VLOOKUP(C38,Players!B:D,3,FALSE) -> 200 | H38: 31
A39: 27 | B39: P | C39: Phil Hughes | D39: =VLOOKUP(C39,Players!B:H,7,FALSE) -> Pitcher | E39: 3200000 | F39: 77 | G39: =VLOOKUP(C39,Players!B:D,3,FALSE) -> 240 | H39: 26
A40: 43 | B40: P | C40: Rafael Soriano | D40: =VLOOKUP(C40,Players!B:H,7,FALSE) -> Pitcher | E40: 11000000 | F40: 73 | G40: =VLOOKUP(C40,Players!B:D,3,FALSE) -> 210 | H40: 32
...

Sheet HR YOY
A1: Tm | B1: League | C1: 2012 HR | D1: 2011 HR
A2: ARI | B2: NL | C2: 165 | D2: 172
A3: ATL | B3: NL | C3: 149 | D3: 173
A4: BAL | B4: AL | C4: 214 | D4: 191
A5: BOS | B5: AL | C5: 165 | D5: 203
A6: CHC | B6: NL | C6: 137 | D6: 148
A7: CHW | B7: AL | C7: 211 | D7: 154
A8: CIN | B8: NL | C8: 172 | D8: 183
A9: CLE | B9: AL | C9: 136 | D9: 154
A10: COL | B10: NL | C10: 166 | D10: 163
A11: DET | B11: AL | C11: 163 | D11: 169
A12: HOU | B12: NL | C12: 146 | D12: 149
A13: KCR | B13: AL | C13: 131 | D13: 95
... A31: WSN | B31: NL | C31: 194 | D31: 154

Sheet AL Team Homeruns
A1: Tm | B1: City | C1: League | D1: 2012 HR | E1: 2011 HR
A2: BAL | B2: Baltimore | C2: AL | D2: 214 | E2: 191
A3: BOS | B3: Boston | C3: AL | D3: 165 | E3: 203
A4: CHW | B4: Chicago | C4: AL | D4: 211 | E4: 154
A5: CLE | B5: Cleveland | C5: AL | D5: 136 | E5: 154
A6: DET | B6: Detroit | C6: AL | D6: 163 | E6: 169
A7: KCR | B7: Kansas City | C7: AL | D7: 131 | E7: 95
A8: LAA | B8: Los Angeles | C8: AL | D8: 187 | E8: 129
A9: MIN | B9: Minnesota | C9: AL | D9: 131 | E9: 103
A10: NYY | B10: New York | C10: AL | D10: 245 | E10: 222
A11: OAK | B11: Oakland | C11: AL | D11: 195 | E11: 114
A12: SEA | B12: Seattle | C12: AL | D12: 149 | E12: 109
A13: TBR | B13: Tampa Bay | C13: AL | D13: 175 | E13: 172
... A15: TOR | B15: Toronto | C15: AL | D15: 198 | E15: 186

Sheet Players
A1: # | B1: Name | C1: Height | D1: Weight | E1: Throws | F1: Bats | G1: Date Of Birth | H1: Type | L1: Height (in)
A2: 43 | B2: Adam Warren | C2: 41427 | D2: 200 | E2: Right | F2: Right | G2: 32014 | H2: Pitcher | J2: 6 | K2: 2 | L2: 74
A3: 13 | B3: Alex Rodriguez | C3: 41428 | D3: 225 | E3: Right | F3: Right | G3: 27602 | H3: Infielder | J3: 6 | K3: 3 | L3: 75
A4: 22 | B4: Andruw Jones | C4: 41426 | D4: 225 | E4: Right | F4: Right | G4: 28238 | H4: Outfielder | J4: 6 | K4: 1 | L4: 73
A5: 46 | B5: Andy Pettitte | C5: 41430 | D5: 225 | E5: Left | F5: Left | G5: 26465 | H5: Pitcher | J5: 6 | K5: 5 | L5: 77
A6: 48 | B6: Boone Logan | C6: 41430 | D6: 215 | E6: Left | F6: Right | G6: 30907 | H6: Pitcher | J6: 6 | K6: 5 | L6: 77
A7: 11 | B7: Brett Gardner | C7: 41404 | D7: 185 | E7: Left | F7: Left | G7: 30552 | H7: Outfielder | J7: 5 | K7: 10 | L7: 70
A8: 45 | B8: Casey McGehee | C8: 41426 | D8: 220 | E8: Right | F8: Right | G8: 30236 | H8: Infielder | J8: 6 | K8: 1 | L8: 73
A9: 52 | B9: CC Sabathia | C9: 41432 | D9: 290 | E9: Left | F9: Left | G9: 29423 | H9: Pitcher | J9: 6 | K9: 7 | L9: 79
A10: 40 | B10: Chad Qualls | C10: 41430 | D10: 240 | E10: Right | F10: Right | G10: 28719 | H10: Pitcher | J10: 6 | K10: 5 | L10: 77
A11: 60 | B11: Chris Dickerson | C11: 41428 | D11: 230 | E11: Left | F11: Left | G11: 30051 | H11: Outfielder | J11: 6 | K11: 3 | L11: 75
A12: 19 | B12: Chris Stewart | C12: 41429 | D12: 210 | E12: Right | F12: Right | G12: 30001 | H12: Catcher | J12: 6 | K12: 4 | L12: 76
A13: 39 | B13: Clay Rapada | C13: 41430 | D13: 200 | E13: Left | F13: Right | G13: 29654 | H13: Pitcher | J13: 6 | K13: 5 | L13: 77
... A46: 43 | B46: Steve Pearce | C46: 41405 | D46: 210 | E46: Right | F46: Right | G46: 30419 | H46: Infielder | J46: 5 | K46: 11 | L46: 71
